<!--
  Dobot CRA Robot Obstacle Navigation Scene for MuJoCo.
  Robot type: arm
  Velocity limits: vx [0, 0.5], wz [-0.3, 0.3]
-->
<mujoco model="dobot-cra_obstacle_navigation">
  <compiler angle="radian" meshdir="." autolimits="true"/>
  <option timestep="0.001" gravity="0 0 -9.81" integrator="implicitfast">
    <flag sensornoise="disable"/>
  </option>
  <default>
    <joint armature="0.01" damping="0.1"/>
    <geom condim="4" friction="1.0 0.005 0.0001"/>
    <motor ctrllimited="true"/>
  </default>
  <asset>
    <texture name="grid" type="2d" builtin="checker" rgb1="0.4 0.4 0.4" rgb2="0.5 0.5 0.5" width="512" height="512"/>
    <material name="grid_mat" texture="grid" texrepeat="10 10" reflectance="0.1"/>
    <material name="obstacle_mat" rgba="0.8 0.2 0.2 1"/>
    <material name="goal_mat" rgba="0.2 0.8 0.2 0.5"/>
    <material name="robot_mat" rgba="0.3 0.3 0.3 1"/>
  </asset>
  <worldbody>
    <geom name="ground" type="plane" size="20 20 0.1" material="grid_mat"/>
    <light name="top_light" pos="0 0 10" dir="0 0 -1" diffuse="0.8 0.8 0.8"/>
    <light name="side_light" pos="5 5 5" dir="-1 -1 -1" diffuse="0.4 0.4 0.4"/>
    <body name="torso" pos="0 0 0.50">
      <inertial mass="8.0" pos="0 0 0" diaginertia="0.3 0.3 0.3"/>
      <geom name="torso_geom" type="cylinder" size="0.15 0.08" material="robot_mat"/>
      <body name="shoulder" pos="0 0 0.15">
        <inertial mass="2.0" pos="0 0 0" diaginertia="0.05 0.05 0.05"/>
        <joint name="shoulder_yaw" type="hinge" axis="0 0 1" range="-3.14 3.14"/>
        <geom name="shoulder_geom" type="sphere" size="0.06" material="robot_mat"/>
        <body name="upper_arm" pos="0 0 0">
          <inertial mass="1.5" pos="0.15 0 0" diaginertia="0.02 0.02 0.02"/>
          <joint name="shoulder_pitch" type="hinge" axis="0 1 0" range="-1.5 1.5"/>
          <geom name="upper_arm_geom" type="capsule" size="0.035" fromto="0 0 0 0.3 0 0" material="robot_mat"/>
          <body name="elbow" pos="0.3 0 0">
            <inertial mass="1.0" pos="0.12 0 0" diaginertia="0.01 0.01 0.01"/>
            <joint name="elbow_pitch" type="hinge" axis="0 1 0" range="-2.5 0"/>
            <geom name="lower_arm_geom" type="capsule" size="0.03" fromto="0 0 0 0.25 0 0" material="robot_mat"/>
            <body name="end_effector" pos="0.25 0 0">
              <inertial mass="0.5" pos="0 0 0" diaginertia="0.005 0.005 0.005"/>
              <geom name="ee_geom" type="sphere" size="0.04" material="robot_mat"/>
              <site name="ee_site" pos="0 0 0"/>
            </body>
          </body>
        </body>
      </body>
      <freejoint name="root"/>
    </body>
    <body name="obstacle_1" pos="2.5 0 0.5" mocap="true">
      <geom name="obs1_geom" type="box" size="0.5 0.5 0.5" material="obstacle_mat" contype="1" conaffinity="1"/>
    </body>
    <body name="obstacle_2" pos="5.0 1.5 0.5" mocap="true">
      <geom name="obs2_geom" type="box" size="0.4 0.4 0.6" material="obstacle_mat" contype="1" conaffinity="1"/>
    </body>
    <body name="obstacle_3" pos="7.0 -1.0 0.5" mocap="true">
      <geom name="obs3_geom" type="cylinder" size="0.3 0.5" material="obstacle_mat" contype="1" conaffinity="1"/>
    </body>
    <body name="goal" pos="10.0 0 0.05">
      <geom name="goal_geom" type="cylinder" size="0.3 0.05" material="goal_mat" contype="0" conaffinity="0"/>
      <site name="goal_site" pos="0 0 0.05"/>
    </body>
  </worldbody>
  <sensor>
    <framepos name="torso_pos" objtype="body" objname="torso"/>
    <framevel name="torso_vel" objtype="body" objname="torso"/>
    <framepos name="ee_pos" objtype="body" objname="end_effector"/>
    <framepos name="goal_pos" objtype="site" objname="goal_site"/>
  </sensor>
  <actuator>
    <motor name="root_x" joint="root" gear="1 0 0 0 0 0" ctrlrange="-100 100"/>
    <motor name="root_y" joint="root" gear="0 1 0 0 0 0" ctrlrange="-100 100"/>
    <motor name="root_yaw" joint="root" gear="0 0 0 0 0 1" ctrlrange="-50 50"/>
    <position name="shoulder_yaw_act" joint="shoulder_yaw" kp="100" ctrlrange="-3.14 3.14"/>
    <position name="shoulder_pitch_act" joint="shoulder_pitch" kp="100" ctrlrange="-1.5 1.5"/>
    <position name="elbow_pitch_act" joint="elbow_pitch" kp="100" ctrlrange="-2.5 0"/>
  </actuator>
</mujoco>
