<mujoco model="go2_obstacle_navigation">
  <compiler angle="radian" autolimits="true"/>
  <option timestep="0.001" gravity="0 0 -9.81" integrator="implicitfast"/>
  <default><joint armature="0.01" damping="0.1"/><geom condim="4" friction="1.0 0.005 0.0001"/></default>
  <asset>
    <texture name="grid" type="2d" builtin="checker" rgb1="0.4 0.4 0.4" rgb2="0.5 0.5 0.5" width="512" height="512"/>
    <material name="grid_mat" texture="grid" texrepeat="10 10" reflectance="0.1"/>
    <material name="obstacle_mat" rgba="0.8 0.2 0.2 1"/>
    <material name="goal_mat" rgba="0.2 0.8 0.2 0.5"/>
    <material name="robot_mat" rgba="0.3 0.3 0.3 1"/>
  </asset>
  <worldbody>
    <geom name="ground" type="plane" size="20 20 0.1" material="grid_mat"/>
    <light name="top" pos="0 0 10" dir="0 0 -1" diffuse="0.8 0.8 0.8"/>
    <body name="torso" pos="0 0 0.5">
      <inertial mass="20.0" pos="0 0 0" diaginertia="0.5 0.5 0.5"/>
      <geom name="torso_geom" type="box" size="0.2 0.15 0.1" material="robot_mat"/>
      <body name="fl_upper" pos="0.2 0.15 -0.05"><inertial mass="2" pos="0 0 -0.15" diaginertia="0.02 0.02 0.02"/><joint name="fl_hip" type="hinge" axis="1 0 0" range="-1 1"/><geom name="fl_ug" type="capsule" size="0.03" fromto="0 0 0 0 0 -0.3" material="robot_mat"/><body name="fl_lower" pos="0 0 -0.3"><inertial mass="1.5" pos="0 0 -0.15" diaginertia="0.01 0.01 0.01"/><joint name="fl_knee" type="hinge" axis="0 1 0" range="-2 0"/><geom name="fl_lg" type="capsule" size="0.025" fromto="0 0 0 0 0 -0.3" material="robot_mat"/><body name="fl_foot" pos="0 0 -0.3"><inertial mass="0.5" pos="0 0 0" diaginertia="0.001 0.001 0.001"/><geom name="fl_fg" type="sphere" size="0.03" material="robot_mat"/><site name="fl_foot_site" pos="0 0 0"/></body></body></body>
      <body name="fr_upper" pos="0.2 -0.15 -0.05"><inertial mass="2" pos="0 0 -0.15" diaginertia="0.02 0.02 0.02"/><joint name="fr_hip" type="hinge" axis="1 0 0" range="-1 1"/><geom name="fr_ug" type="capsule" size="0.03" fromto="0 0 0 0 0 -0.3" material="robot_mat"/><body name="fr_lower" pos="0 0 -0.3"><inertial mass="1.5" pos="0 0 -0.15" diaginertia="0.01 0.01 0.01"/><joint name="fr_knee" type="hinge" axis="0 1 0" range="-2 0"/><geom name="fr_lg" type="capsule" size="0.025" fromto="0 0 0 0 0 -0.3" material="robot_mat"/><body name="fr_foot" pos="0 0 -0.3"><inertial mass="0.5" pos="0 0 0" diaginertia="0.001 0.001 0.001"/><geom name="fr_fg" type="sphere" size="0.03" material="robot_mat"/><site name="fr_foot_site" pos="0 0 0"/></body></body></body>
      <body name="rl_upper" pos="-0.2 0.15 -0.05"><inertial mass="2" pos="0 0 -0.15" diaginertia="0.02 0.02 0.02"/><joint name="rl_hip" type="hinge" axis="1 0 0" range="-1 1"/><geom name="rl_ug" type="capsule" size="0.03" fromto="0 0 0 0 0 -0.3" material="robot_mat"/><body name="rl_lower" pos="0 0 -0.3"><inertial mass="1.5" pos="0 0 -0.15" diaginertia="0.01 0.01 0.01"/><joint name="rl_knee" type="hinge" axis="0 1 0" range="-2 0"/><geom name="rl_lg" type="capsule" size="0.025" fromto="0 0 0 0 0 -0.3" material="robot_mat"/><body name="rl_foot" pos="0 0 -0.3"><inertial mass="0.5" pos="0 0 0" diaginertia="0.001 0.001 0.001"/><geom name="rl_fg" type="sphere" size="0.03" material="robot_mat"/><site name="rl_foot_site" pos="0 0 0"/></body></body></body>
      <body name="rr_upper" pos="-0.2 -0.15 -0.05"><inertial mass="2" pos="0 0 -0.15" diaginertia="0.02 0.02 0.02"/><joint name="rr_hip" type="hinge" axis="1 0 0" range="-1 1"/><geom name="rr_ug" type="capsule" size="0.03" fromto="0 0 0 0 0 -0.3" material="robot_mat"/><body name="rr_lower" pos="0 0 -0.3"><inertial mass="1.5" pos="0 0 -0.15" diaginertia="0.01 0.01 0.01"/><joint name="rr_knee" type="hinge" axis="0 1 0" range="-2 0"/><geom name="rr_lg" type="capsule" size="0.025" fromto="0 0 0 0 0 -0.3" material="robot_mat"/><body name="rr_foot" pos="0 0 -0.3"><inertial mass="0.5" pos="0 0 0" diaginertia="0.001 0.001 0.001"/><geom name="rr_fg" type="sphere" size="0.03" material="robot_mat"/><site name="rr_foot_site" pos="0 0 0"/></body></body></body>
      <freejoint name="root"/>
    </body>
    <body name="obstacle_1" pos="2.5 0 0.5"><geom name="obs1" type="box" size="0.5 0.5 0.5" material="obstacle_mat" contype="1" conaffinity="1"/></body>
    <body name="obstacle_2" pos="5.0 1.5 0.5"><geom name="obs2" type="box" size="0.4 0.4 0.6" material="obstacle_mat" contype="1" conaffinity="1"/></body>
    <body name="obstacle_3" pos="7.0 -1.0 0.5"><geom name="obs3" type="cylinder" size="0.3 0.5" material="obstacle_mat" contype="1" conaffinity="1"/></body>
    <body name="goal" pos="10.0 0 0.05"><geom name="goal_geom" type="cylinder" size="0.3 0.05" material="goal_mat" contype="0" conaffinity="0"/><site name="goal_site" pos="0 0 0.05"/></body>
  </worldbody>
  <sensor>
    <framepos name="torso_pos" objtype="body" objname="torso"/>
  </sensor>
</mujoco>