<mujoco model="tron1_obstacle_navigation">
  <compiler angle="radian" autolimits="true"/>
  <option timestep="0.001" gravity="0 0 -9.81" integrator="implicitfast"/>
  <default><joint armature="0.01" damping="0.1"/><geom condim="4" friction="1.0 0.005 0.0001"/></default>
  <asset>
    <texture name="grid" type="2d" builtin="checker" rgb1="0.4 0.4 0.4" rgb2="0.5 0.5 0.5" width="512" height="512"/>
    <material name="grid_mat" texture="grid" texrepeat="10 10" reflectance="0.1"/>
    <material name="obstacle_mat" rgba="0.8 0.2 0.2 1"/>
    <material name="goal_mat" rgba="0.2 0.8 0.2 0.5"/>
    <material name="robot_mat" rgba="0.3 0.3 0.3 1"/>
  </asset>
  <worldbody>
    <geom name="ground" type="plane" size="20 20 0.1" material="grid_mat"/>
    <light name="top" pos="0 0 10" dir="0 0 -1" diffuse="0.8 0.8 0.8"/>
    <body name="torso" pos="0 0 0.78">
      <inertial mass="35.0" pos="0 0 0" diaginertia="1.0 1.0 1.0"/>
      <geom name="torso_geom" type="capsule" size="0.15" fromto="0 -0.12 0 0 0.12 0" material="robot_mat"/>
      <body name="head" pos="0 0 0.25"><inertial mass="2.0" pos="0 0 0" diaginertia="0.1 0.1 0.1"/><geom name="head_geom" type="sphere" size="0.12" material="robot_mat"/></body>
      <body name="left_thigh" pos="0 0.1 -0.2"><inertial mass="5.0" pos="0 0 -0.2" diaginertia="0.1 0.1 0.1"/><joint name="left_hip" type="hinge" axis="1 0 0" range="-1.5 1.5"/><geom name="lt_g" type="capsule" size="0.06" fromto="0 0 0 0 0 -0.4" material="robot_mat"/><body name="left_shin" pos="0 0 -0.4"><inertial mass="4.0" pos="0 0 -0.2" diaginertia="0.08 0.08 0.08"/><joint name="left_knee" type="hinge" axis="0 1 0" range="-2.5 0"/><geom name="ls_g" type="capsule" size="0.05" fromto="0 0 0 0 0 -0.4" material="robot_mat"/><body name="left_foot" pos="0 0 -0.4"><inertial mass="1.0" pos="0 0 -0.03" diaginertia="0.01 0.01 0.01"/><geom name="lf_g" type="box" size="0.08 0.04 0.03" pos="0 0 -0.03" material="robot_mat"/></body></body></body>
      <body name="right_thigh" pos="0 -0.1 -0.2"><inertial mass="5.0" pos="0 0 -0.2" diaginertia="0.1 0.1 0.1"/><joint name="right_hip" type="hinge" axis="1 0 0" range="-1.5 1.5"/><geom name="rt_g" type="capsule" size="0.06" fromto="0 0 0 0 0 -0.4" material="robot_mat"/><body name="right_shin" pos="0 0 -0.4"><inertial mass="4.0" pos="0 0 -0.2" diaginertia="0.08 0.08 0.08"/><joint name="right_knee" type="hinge" axis="0 1 0" range="-2.5 0"/><geom name="rs_g" type="capsule" size="0.05" fromto="0 0 0 0 0 -0.4" material="robot_mat"/><body name="right_foot" pos="0 0 -0.4"><inertial mass="1.0" pos="0 0 -0.03" diaginertia="0.01 0.01 0.01"/><geom name="rf_g" type="box" size="0.08 0.04 0.03" pos="0 0 -0.03" material="robot_mat"/></body></body></body>
      <freejoint name="root"/>
    </body>
    <body name="obstacle_1" pos="2.5 0 0.5"><geom name="obs1" type="box" size="0.5 0.5 0.5" material="obstacle_mat" contype="1" conaffinity="1"/></body>
    <body name="obstacle_2" pos="5.0 1.5 0.5"><geom name="obs2" type="box" size="0.4 0.4 0.6" material="obstacle_mat" contype="1" conaffinity="1"/></body>
    <body name="obstacle_3" pos="7.0 -1.0 0.5"><geom name="obs3" type="cylinder" size="0.3 0.5" material="obstacle_mat" contype="1" conaffinity="1"/></body>
    <body name="goal" pos="10.0 0 0.05"><geom name="goal_geom" type="cylinder" size="0.3 0.05" material="goal_mat" contype="0" conaffinity="0"/><site name="goal_site" pos="0 0 0.05"/></body>
  </worldbody>
  <sensor>
    <framepos name="torso_pos" objtype="body" objname="torso"/>
    <framevel name="torso_vel" objtype="body" objname="torso"/>
    <framepos name="goal_pos" objtype="site" objname="goal_site"/>
  </sensor>
</mujoco>